2025-05-30 18:05:07,333 INFO: Spjald startup [in /home/edvin/Prog/spjald/app/__init__.py:77]
2025-05-30 18:07:45,860 ERROR: Exception on / [GET] [in /home/edvin/Prog/spjald/venv/lib/python3.12/site-packages/flask/app.py:1414]
Traceback (most recent call last):
  File "/home/edvin/Prog/spjald/venv/lib/python3.12/site-packages/flask/app.py", line 2190, in wsgi_app
    response = self.full_dispatch_request()
               ^^^^^^^^^^^^^^^^^^^^^^^^^^^^
  File "/home/edvin/Prog/spjald/venv/lib/python3.12/site-packages/flask/app.py", line 1486, in full_dispatch_request
    rv = self.handle_user_exception(e)
         ^^^^^^^^^^^^^^^^^^^^^^^^^^^^^
  File "/home/edvin/Prog/spjald/venv/lib/python3.12/site-packages/flask/app.py", line 1482, in full_dispatch_request
    rv = self.preprocess_request()
         ^^^^^^^^^^^^^^^^^^^^^^^^^
  File "/home/edvin/Prog/spjald/venv/lib/python3.12/site-packages/flask/app.py", line 1974, in preprocess_request
    rv = self.ensure_sync(before_func)()
         ^^^^^^^^^^^^^^^^^^^^^^^^^^^^^^^
  File "/home/edvin/Prog/spjald/app/main/routes.py", line 14, in before_request
    if current_user.is_authenticated:
       ^^^^^^^^^^^^^^^^^^^^^^^^^^^^^
  File "/home/edvin/Prog/spjald/venv/lib/python3.12/site-packages/werkzeug/local.py", line 311, in __get__
    obj = instance._get_current_object()
          ^^^^^^^^^^^^^^^^^^^^^^^^^^^^^^
  File "/home/edvin/Prog/spjald/venv/lib/python3.12/site-packages/werkzeug/local.py", line 515, in _get_current_object
    return get_name(local())
                    ^^^^^^^
  File "/home/edvin/Prog/spjald/venv/lib/python3.12/site-packages/flask_login/utils.py", line 25, in <lambda>
    current_user = LocalProxy(lambda: _get_user())
                                      ^^^^^^^^^^^
  File "/home/edvin/Prog/spjald/venv/lib/python3.12/site-packages/flask_login/utils.py", line 370, in _get_user
    current_app.login_manager._load_user()
  File "/home/edvin/Prog/spjald/venv/lib/python3.12/site-packages/flask_login/login_manager.py", line 347, in _load_user
    raise Exception(
Exception: Missing user_loader or request_loader. Refer to http://flask-login.readthedocs.io/#how-it-works for more info.
2025-05-30 18:07:45,938 ERROR: Exception on /favicon.ico [GET] [in /home/edvin/Prog/spjald/venv/lib/python3.12/site-packages/flask/app.py:1414]
Traceback (most recent call last):
  File "/home/edvin/Prog/spjald/venv/lib/python3.12/site-packages/flask/app.py", line 2190, in wsgi_app
    response = self.full_dispatch_request()
               ^^^^^^^^^^^^^^^^^^^^^^^^^^^^
  File "/home/edvin/Prog/spjald/venv/lib/python3.12/site-packages/flask/app.py", line 1486, in full_dispatch_request
    rv = self.handle_user_exception(e)
         ^^^^^^^^^^^^^^^^^^^^^^^^^^^^^
  File "/home/edvin/Prog/spjald/venv/lib/python3.12/site-packages/flask/app.py", line 1482, in full_dispatch_request
    rv = self.preprocess_request()
         ^^^^^^^^^^^^^^^^^^^^^^^^^
  File "/home/edvin/Prog/spjald/venv/lib/python3.12/site-packages/flask/app.py", line 1974, in preprocess_request
    rv = self.ensure_sync(before_func)()
         ^^^^^^^^^^^^^^^^^^^^^^^^^^^^^^^
  File "/home/edvin/Prog/spjald/app/main/routes.py", line 14, in before_request
    if current_user.is_authenticated:
       ^^^^^^^^^^^^^^^^^^^^^^^^^^^^^
  File "/home/edvin/Prog/spjald/venv/lib/python3.12/site-packages/werkzeug/local.py", line 311, in __get__
    obj = instance._get_current_object()
          ^^^^^^^^^^^^^^^^^^^^^^^^^^^^^^
  File "/home/edvin/Prog/spjald/venv/lib/python3.12/site-packages/werkzeug/local.py", line 515, in _get_current_object
    return get_name(local())
                    ^^^^^^^
  File "/home/edvin/Prog/spjald/venv/lib/python3.12/site-packages/flask_login/utils.py", line 25, in <lambda>
    current_user = LocalProxy(lambda: _get_user())
                                      ^^^^^^^^^^^
  File "/home/edvin/Prog/spjald/venv/lib/python3.12/site-packages/flask_login/utils.py", line 370, in _get_user
    current_app.login_manager._load_user()
  File "/home/edvin/Prog/spjald/venv/lib/python3.12/site-packages/flask_login/login_manager.py", line 347, in _load_user
    raise Exception(
Exception: Missing user_loader or request_loader. Refer to http://flask-login.readthedocs.io/#how-it-works for more info.
2025-05-30 18:59:13,388 INFO: Spjald startup [in /home/edvin/Prog/spjald/app/__init__.py:86]
2025-05-30 18:59:16,258 ERROR: Exception on / [GET] [in /home/edvin/Prog/spjald/venv/lib/python3.12/site-packages/flask/app.py:1414]
Traceback (most recent call last):
  File "/home/edvin/Prog/spjald/venv/lib/python3.12/site-packages/flask/app.py", line 2190, in wsgi_app
    response = self.full_dispatch_request()
               ^^^^^^^^^^^^^^^^^^^^^^^^^^^^
  File "/home/edvin/Prog/spjald/venv/lib/python3.12/site-packages/flask/app.py", line 1486, in full_dispatch_request
    rv = self.handle_user_exception(e)
         ^^^^^^^^^^^^^^^^^^^^^^^^^^^^^
  File "/home/edvin/Prog/spjald/venv/lib/python3.12/site-packages/flask/app.py", line 1484, in full_dispatch_request
    rv = self.dispatch_request()
         ^^^^^^^^^^^^^^^^^^^^^^^
  File "/home/edvin/Prog/spjald/venv/lib/python3.12/site-packages/flask/app.py", line 1469, in dispatch_request
    return self.ensure_sync(self.view_functions[rule.endpoint])(**view_args)
           ^^^^^^^^^^^^^^^^^^^^^^^^^^^^^^^^^^^^^^^^^^^^^^^^^^^^^^^^^^^^^^^^^
  File "/home/edvin/Prog/spjald/venv/lib/python3.12/site-packages/flask_login/utils.py", line 290, in decorated_view
    return current_app.ensure_sync(func)(*args, **kwargs)
           ^^^^^^^^^^^^^^^^^^^^^^^^^^^^^^^^^^^^^^^^^^^^^^
  File "/home/edvin/Prog/spjald/app/main/routes.py", line 23, in index
    posts = current_user.followed_posts().paginate(
            ^^^^^^^^^^^^^^^^^^^^^^^^^^^^^^^^^^^^^^^
TypeError: Query.paginate() takes 1 positional argument but 4 were given
